---
title: Try...Catch...Finally Deyimi (Visual Basic)
ms.date: 07/20/2015
ms.prod: .net
ms.reviewer: 
ms.suite: 
ms.technology: devlang-visual-basic
ms.topic: article
f1_keywords:
- vb.Try...Catch...Finally
- vb.when
- vb.Finally
- vb.Catch
- vb.Try
helpviewer_keywords:
- Try...Catch...Finally statements
- Try statement [Visual Basic]
- try-catch exception handling, Try...Catch...Finally statements
- error handling, while running code
- Try statement [Visual Basic], Try...Catch...Finally
- Finally keyword [Visual Basic], Try...Catch...Finally
- Catch statement [Visual Basic]
- When keyword [Visual Basic]
- Visual Basic code, handling errors while running
- structured exception handling, Try...Catch...Finally statements
ms.assetid: d6488026-ccb3-42b8-a810-0d97b9d6472b
caps.latest.revision: "69"
author: dotnet-bot
ms.author: dotnetcontent
ms.openlocfilehash: 08de4939960d8297269c82b1b040537dd43f3038
ms.sourcegitcommit: 4f3fef493080a43e70e951223894768d36ce430a
ms.translationtype: MT
ms.contentlocale: tr-TR
ms.lasthandoff: 11/21/2017
---
# <a name="trycatchfinally-statement-visual-basic"></a><span data-ttu-id="315d1-102">Try...Catch...Finally Deyimi (Visual Basic)</span><span class="sxs-lookup"><span data-stu-id="315d1-102">Try...Catch...Finally Statement (Visual Basic)</span></span>
<span data-ttu-id="315d1-103">Belirli bir kod bloğu içinde hala kod çalıştırılırken ortaya çıkabilecek bazı veya tüm olası hataları işlemek için bir yol sağlar.</span><span class="sxs-lookup"><span data-stu-id="315d1-103">Provides a way to handle some or all possible errors that may occur in a given block of code, while still running code.</span></span>  
  
## <a name="syntax"></a><span data-ttu-id="315d1-104">Sözdizimi</span><span class="sxs-lookup"><span data-stu-id="315d1-104">Syntax</span></span>  
  
```  
Try  
    [ tryStatements ]  
    [ Exit Try ]  
[ Catch [ exception [ As type ] ] [ When expression ]  
    [ catchStatements ]  
    [ Exit Try ] ]  
[ Catch ... ]  
[ Finally  
    [ finallyStatements ] ]  
End Try  
```  
  
## <a name="parts"></a><span data-ttu-id="315d1-105">Bölümler</span><span class="sxs-lookup"><span data-stu-id="315d1-105">Parts</span></span>  
  
|<span data-ttu-id="315d1-106">Terim</span><span class="sxs-lookup"><span data-stu-id="315d1-106">Term</span></span>|<span data-ttu-id="315d1-107">Tanım</span><span class="sxs-lookup"><span data-stu-id="315d1-107">Definition</span></span>|  
|---|---|  
|`tryStatements`|<span data-ttu-id="315d1-108">İsteğe bağlı.</span><span class="sxs-lookup"><span data-stu-id="315d1-108">Optional.</span></span> <span data-ttu-id="315d1-109">Deyim, burada bir hata oluşabilir.</span><span class="sxs-lookup"><span data-stu-id="315d1-109">Statement(s) where an error can occur.</span></span> <span data-ttu-id="315d1-110">Bileşik deyim olabilir.</span><span class="sxs-lookup"><span data-stu-id="315d1-110">Can be a compound statement.</span></span>|  
|`Catch`|<span data-ttu-id="315d1-111">İsteğe bağlı.</span><span class="sxs-lookup"><span data-stu-id="315d1-111">Optional.</span></span> <span data-ttu-id="315d1-112">Birden çok `Catch` izin engeller.</span><span class="sxs-lookup"><span data-stu-id="315d1-112">Multiple `Catch` blocks permitted.</span></span> <span data-ttu-id="315d1-113">Bir özel durum işleme sırasında oluşursa `Try` engellemek, her `Catch` deyimi, özel durum ile işleme olup olmadığını belirlemek için metinsel sırayla incelenir `exception` oluşturuldu özel durumu temsil eden.</span><span class="sxs-lookup"><span data-stu-id="315d1-113">If an exception occurs when processing the `Try` block, each `Catch` statement is examined in textual order to determine whether it handles the exception, with `exception` representing the exception that has been thrown.</span></span>|  
|`exception`|<span data-ttu-id="315d1-114">İsteğe bağlı.</span><span class="sxs-lookup"><span data-stu-id="315d1-114">Optional.</span></span> <span data-ttu-id="315d1-115">Herhangi bir değişken adı.</span><span class="sxs-lookup"><span data-stu-id="315d1-115">Any variable name.</span></span> <span data-ttu-id="315d1-116">Başlangıç değeri `exception` atılmış hata değeri.</span><span class="sxs-lookup"><span data-stu-id="315d1-116">The initial value of `exception` is the value of the thrown error.</span></span> <span data-ttu-id="315d1-117">İle kullanılan `Catch` hata belirtmek için yakalandı.</span><span class="sxs-lookup"><span data-stu-id="315d1-117">Used with `Catch` to specify the error caught.</span></span> <span data-ttu-id="315d1-118">Atlanırsa, `Catch` deyimi özel durumları yakalar.</span><span class="sxs-lookup"><span data-stu-id="315d1-118">If omitted, the `Catch` statement catches any exception.</span></span>|  
|`type`|<span data-ttu-id="315d1-119">İsteğe bağlı.</span><span class="sxs-lookup"><span data-stu-id="315d1-119">Optional.</span></span> <span data-ttu-id="315d1-120">Sınıf filtre türünü belirtir.</span><span class="sxs-lookup"><span data-stu-id="315d1-120">Specifies the type of class filter.</span></span> <span data-ttu-id="315d1-121">Varsa değerini `exception` tarafından belirtilen türde `type` veya türetilmiş bir tür tanımlayıcı için özel durum nesnesi bağlı olur.</span><span class="sxs-lookup"><span data-stu-id="315d1-121">If the value of `exception` is of the type specified by `type` or of a derived type, the identifier becomes bound to the exception object.</span></span>|  
|`When`|<span data-ttu-id="315d1-122">İsteğe bağlı.</span><span class="sxs-lookup"><span data-stu-id="315d1-122">Optional.</span></span> <span data-ttu-id="315d1-123">A `Catch` deyimiyle bir `When` yan tümcesi özel durumları yakalar yalnızca `expression` değerlendiren `True`.</span><span class="sxs-lookup"><span data-stu-id="315d1-123">A `Catch` statement with a `When` clause catches exceptions only when `expression` evaluates to `True`.</span></span> <span data-ttu-id="315d1-124">A `When` yan tümcesi, yalnızca özel durum türünü denetledikten sonra uygulanır ve `expression` özel durumu temsil eden tanımlayıcı başvurabilir.</span><span class="sxs-lookup"><span data-stu-id="315d1-124">A `When` clause is applied only after checking the type of the exception, and `expression` may refer to the identifier representing the exception.</span></span>|  
|`expression`|<span data-ttu-id="315d1-125">İsteğe bağlı.</span><span class="sxs-lookup"><span data-stu-id="315d1-125">Optional.</span></span> <span data-ttu-id="315d1-126">Örtük olarak dönüştürülebilir olmalıdır `Boolean`.</span><span class="sxs-lookup"><span data-stu-id="315d1-126">Must be implicitly convertible to `Boolean`.</span></span> <span data-ttu-id="315d1-127">Genel filtre açıklar herhangi bir ifade.</span><span class="sxs-lookup"><span data-stu-id="315d1-127">Any expression that describes a generic filter.</span></span> <span data-ttu-id="315d1-128">Genellikle, hata numarasına göre filtre uygulamak için kullanılır.</span><span class="sxs-lookup"><span data-stu-id="315d1-128">Typically used to filter by error number.</span></span> <span data-ttu-id="315d1-129">İle kullanılan `When` koşullar altında hata belirledi belirtmek için anahtar sözcüğü.</span><span class="sxs-lookup"><span data-stu-id="315d1-129">Used with `When` keyword to specify circumstances under which the error is caught.</span></span>|  
|`catchStatements`|<span data-ttu-id="315d1-130">İsteğe bağlı.</span><span class="sxs-lookup"><span data-stu-id="315d1-130">Optional.</span></span> <span data-ttu-id="315d1-131">Deyim ilişkili oluşan hataları işlemek için `Try` bloğu.</span><span class="sxs-lookup"><span data-stu-id="315d1-131">Statement(s) to handle errors that occur in the associated `Try` block.</span></span> <span data-ttu-id="315d1-132">Bileşik deyim olabilir.</span><span class="sxs-lookup"><span data-stu-id="315d1-132">Can be a compound statement.</span></span>|  
|`Exit Try`|<span data-ttu-id="315d1-133">İsteğe bağlı.</span><span class="sxs-lookup"><span data-stu-id="315d1-133">Optional.</span></span> <span data-ttu-id="315d1-134">İşyeri dışında keser anahtar sözcüğü `Try...Catch...Finally` yapısı.</span><span class="sxs-lookup"><span data-stu-id="315d1-134">Keyword that breaks out of the `Try...Catch...Finally` structure.</span></span> <span data-ttu-id="315d1-135">Yürütme hemen koduyla sürdürür `End Try` deyimi.</span><span class="sxs-lookup"><span data-stu-id="315d1-135">Execution resumes with the code immediately following the `End Try` statement.</span></span> <span data-ttu-id="315d1-136">`Finally` Deyimi hala yürütülür.</span><span class="sxs-lookup"><span data-stu-id="315d1-136">The `Finally` statement will still be executed.</span></span> <span data-ttu-id="315d1-137">İçinde izin verilmiyor `Finally` engeller.</span><span class="sxs-lookup"><span data-stu-id="315d1-137">Not allowed in `Finally` blocks.</span></span>|  
|`Finally`|<span data-ttu-id="315d1-138">İsteğe bağlı.</span><span class="sxs-lookup"><span data-stu-id="315d1-138">Optional.</span></span> <span data-ttu-id="315d1-139">A `Finally` blok yürütme herhangi bir kısmını ayrıldığında her zaman yürütülür `Try...Catch` deyimi.</span><span class="sxs-lookup"><span data-stu-id="315d1-139">A `Finally` block is always executed when execution leaves any part of the `Try...Catch` statement.</span></span>|  
|`finallyStatements`|<span data-ttu-id="315d1-140">İsteğe bağlı.</span><span class="sxs-lookup"><span data-stu-id="315d1-140">Optional.</span></span> <span data-ttu-id="315d1-141">Tüm diğer işlenirken hata gerçekleştikten sonra yürütülür deyim.</span><span class="sxs-lookup"><span data-stu-id="315d1-141">Statement(s) that are executed after all other error processing has occurred.</span></span>|  
|`End Try`|<span data-ttu-id="315d1-142">Sonlandırır `Try...Catch...Finally` yapısı.</span><span class="sxs-lookup"><span data-stu-id="315d1-142">Terminates the `Try...Catch...Finally` structure.</span></span>|  
  
## <a name="remarks"></a><span data-ttu-id="315d1-143">Açıklamalar</span><span class="sxs-lookup"><span data-stu-id="315d1-143">Remarks</span></span>  
 <span data-ttu-id="315d1-144">Belirli bir özel durum kodu belirli bir bölümü sırasında oluşabilecek bekliyorsanız, kod yerleştirecek bir `Try` engelleme ve kullanmak bir `Catch` denetimi korumak ve bu durum oluşursa özel durumu işlemek için blok.</span><span class="sxs-lookup"><span data-stu-id="315d1-144">If you expect that a particular exception might occur during a particular section of code, put the code in a `Try` block and use a `Catch` block to retain control and handle the exception if it occurs.</span></span>  
  
 <span data-ttu-id="315d1-145">A `Try…Catch` deyimi oluşur bir `Try` blok izlenen bir veya daha fazla tarafından `Catch` yan tümceleri çeşitli özel durumlar için işleyiciler belirleyin.</span><span class="sxs-lookup"><span data-stu-id="315d1-145">A `Try…Catch` statement consists of a `Try` block followed by one or more `Catch` clauses, which specify handlers for various exceptions.</span></span> <span data-ttu-id="315d1-146">Ne zaman özel durum bir `Try` bloğu [!INCLUDE[vbprvb](~/includes/vbprvb-md.md)] arar `Catch` özel durumu işler deyimi.</span><span class="sxs-lookup"><span data-stu-id="315d1-146">When an exception is thrown in a `Try` block, [!INCLUDE[vbprvb](~/includes/vbprvb-md.md)] looks for the `Catch` statement that handles the exception.</span></span> <span data-ttu-id="315d1-147">Eşleşen bir varsa `Catch` deyimi bulunamadı, [!INCLUDE[vbprvb](~/includes/vbprvb-md.md)] geçerli yöntemi, vb. çağrı yığını çağrılan yöntemi inceler.</span><span class="sxs-lookup"><span data-stu-id="315d1-147">If a matching `Catch` statement is not found, [!INCLUDE[vbprvb](~/includes/vbprvb-md.md)] examines the method that called the current method, and so on up the call stack.</span></span> <span data-ttu-id="315d1-148">Öyle değilse `Catch` blok bulunursa, [!INCLUDE[vbprvb](~/includes/vbprvb-md.md)] kullanıcıya bir işlenmeyen özel durum iletisi görüntüler ve programın yürütülmesi durdurur.</span><span class="sxs-lookup"><span data-stu-id="315d1-148">If no `Catch` block is found, [!INCLUDE[vbprvb](~/includes/vbprvb-md.md)] displays an unhandled exception message to the user and stops execution of the program.</span></span>  
  
 <span data-ttu-id="315d1-149">Birden fazla kullanabilirsiniz `Catch` deyiminde bir `Try…Catch` deyimi.</span><span class="sxs-lookup"><span data-stu-id="315d1-149">You can use more than one `Catch` statement in a `Try…Catch` statement.</span></span> <span data-ttu-id="315d1-150">Bu sırasını yaparsanız `Catch` yan tümceleri olduğundan önemli sırayla incelenir.</span><span class="sxs-lookup"><span data-stu-id="315d1-150">If you do this, the order of the `Catch` clauses is significant because they are examined in order.</span></span> <span data-ttu-id="315d1-151">Daha fazla özel durum daha az yayına önce yakalar.</span><span class="sxs-lookup"><span data-stu-id="315d1-151">Catch the more specific exceptions before the less specific ones.</span></span>  
  
 <span data-ttu-id="315d1-152">Aşağıdaki `Catch` deyimi koşullar az özgüdür ve tüm yakalar öğesinden türetilen özel durumları <xref:System.Exception> sınıfı.</span><span class="sxs-lookup"><span data-stu-id="315d1-152">The following `Catch` statement conditions are the least specific, and will catch all exceptions that derive from the <xref:System.Exception> class.</span></span> <span data-ttu-id="315d1-153">Normalde bu değişimler birini son kullanmalıdır `Catch` engelleyin `Try...Catch...Finally` beklediğiniz tüm belirli özel durumları yakalama sonra yapısı.</span><span class="sxs-lookup"><span data-stu-id="315d1-153">You should ordinarily use one of these variations as the last `Catch` block in the `Try...Catch...Finally` structure, after catching all the specific exceptions you expect.</span></span> <span data-ttu-id="315d1-154">Denetim akışı hiçbir zaman ulaşmak bir `Catch` ya da bu değişimler izler bloğu.</span><span class="sxs-lookup"><span data-stu-id="315d1-154">Control flow can never reach a `Catch` block that follows either of these variations.</span></span>  
  
-   <span data-ttu-id="315d1-155">`type` Olan `Exception`, örneğin:`Catch ex As Exception`</span><span class="sxs-lookup"><span data-stu-id="315d1-155">The `type` is `Exception`, for example: `Catch ex As Exception`</span></span>  
  
-   <span data-ttu-id="315d1-156">Deyim sahip olmayan `exception` değişken, örneğin:`Catch`</span><span class="sxs-lookup"><span data-stu-id="315d1-156">The statement has no `exception` variable, for example: `Catch`</span></span>  
  
 <span data-ttu-id="315d1-157">Zaman bir `Try…Catch…Finally` deyimi iç içe başka bir programda `Try` bloğu [!INCLUDE[vbprvb](~/includes/vbprvb-md.md)] önce her inceler `Catch` ise en içteki deyiminde `Try` bloğu.</span><span class="sxs-lookup"><span data-stu-id="315d1-157">When a `Try…Catch…Finally` statement is nested in another `Try` block, [!INCLUDE[vbprvb](~/includes/vbprvb-md.md)] first examines each `Catch` statement in the innermost `Try` block.</span></span> <span data-ttu-id="315d1-158">Eşleşme varsa `Catch` deyimi bulunursa, aramaya devam eder `Catch` bilgilerinin dış `Try…Catch…Finally` bloğu.</span><span class="sxs-lookup"><span data-stu-id="315d1-158">If no matching `Catch` statement is found, the search proceeds to the `Catch` statements of the outer `Try…Catch…Finally` block.</span></span>  
  
 <span data-ttu-id="315d1-159">Yerel değişkenler arasından bir `Try` blok kullanılabilir olmayan bir `Catch` ayrı blokları olduklarından engelleyin.</span><span class="sxs-lookup"><span data-stu-id="315d1-159">Local variables from a `Try` block are not available in a `Catch` block because they are separate blocks.</span></span> <span data-ttu-id="315d1-160">Birden fazla bloğu içinde bir değişken kullanmak istiyorsanız, dışında değişkeni bildirme `Try...Catch...Finally` yapısı.</span><span class="sxs-lookup"><span data-stu-id="315d1-160">If you want to use a variable in more than one block, declare the variable outside the `Try...Catch...Finally` structure.</span></span>  
  
> [!TIP]
>  <span data-ttu-id="315d1-161">`Try…Catch…Finally` Deyimi bir IntelliSense kod parçacığı olarak kullanılabilir.</span><span class="sxs-lookup"><span data-stu-id="315d1-161">The `Try…Catch…Finally` statement is available as an IntelliSense code snippet.</span></span> <span data-ttu-id="315d1-162">Kod parçacıkları Yöneticisi'nde **kod düzenleri - varsa, her biri için Try Catch, özellik, vb.**ve ardından **hata işleme (özel durumlar)**.</span><span class="sxs-lookup"><span data-stu-id="315d1-162">In the Code Snippets Manager, expand **Code Patterns - If, For Each, Try Catch, Property, etc**, and then **Error Handling (Exceptions)**.</span></span> <span data-ttu-id="315d1-163">Daha fazla bilgi için bkz: [kod parçacıkları](/visualstudio/ide/code-snippets).</span><span class="sxs-lookup"><span data-stu-id="315d1-163">For more information, see [Code Snippets](/visualstudio/ide/code-snippets).</span></span>  
  
## <a name="finally-block"></a><span data-ttu-id="315d1-164">Finally bloğu</span><span class="sxs-lookup"><span data-stu-id="315d1-164">Finally Block</span></span>  
 <span data-ttu-id="315d1-165">Çıkmadan önce çalıştırmanız gereken bir veya daha fazla deyimleri varsa `Try` yapısı, kullanan bir `Finally` bloğu.</span><span class="sxs-lookup"><span data-stu-id="315d1-165">If you have one or more statements that must run before you exit the `Try` structure, use a `Finally` block.</span></span> <span data-ttu-id="315d1-166">Denetim geçtiği `Finally` yalnızca dışı geçirmeden önce engelle `Try…Catch` yapısı.</span><span class="sxs-lookup"><span data-stu-id="315d1-166">Control passes to the `Finally` block just before it passes out of the `Try…Catch` structure.</span></span> <span data-ttu-id="315d1-167">İçinde herhangi bir yerden bir özel durum oluştuğunda dahi, bu durum geçerlidir `Try` yapısı.</span><span class="sxs-lookup"><span data-stu-id="315d1-167">This is true even if an exception occurs anywhere inside the `Try` structure.</span></span>  
  
 <span data-ttu-id="315d1-168">A `Finally` blok, bir özel durum olsa bile, herhangi bir kod çalıştırmasını yürütmeniz gerekir için yararlıdır.</span><span class="sxs-lookup"><span data-stu-id="315d1-168">A `Finally` block is useful for running any code that must execute even if there is an exception.</span></span> <span data-ttu-id="315d1-169">Denetim iletilir `Finally` bağımsız olarak nasıl blok `Try...Catch` engelleme çıkar.</span><span class="sxs-lookup"><span data-stu-id="315d1-169">Control is passed to the `Finally` block regardless of how the `Try...Catch` block exits.</span></span>  
  
 <span data-ttu-id="315d1-170">Kodda bir `Finally` kodunuzu karşılaşırsa bile çalışır engelleme bir `Return` deyiminde bir `Try` veya `Catch` bloğu.</span><span class="sxs-lookup"><span data-stu-id="315d1-170">The code in a `Finally` block runs even if your code encounters a `Return` statement in a `Try` or `Catch` block.</span></span> <span data-ttu-id="315d1-171">Denetim gelen geçirmek olmayan bir `Try` veya `Catch` engelleme karşılık gelen `Finally` aşağıdaki durumlarda engelle:</span><span class="sxs-lookup"><span data-stu-id="315d1-171">Control does not pass from a `Try` or `Catch` block to the corresponding `Finally` block in the following cases:</span></span>  
  
-   <span data-ttu-id="315d1-172">Bir [End deyimi](../../../visual-basic/language-reference/statements/end-statement.md) içinde karşılaştı `Try` veya `Catch` bloğu.</span><span class="sxs-lookup"><span data-stu-id="315d1-172">An [End Statement](../../../visual-basic/language-reference/statements/end-statement.md) is encountered in the `Try` or `Catch` block.</span></span>  
  
-   <span data-ttu-id="315d1-173">A <xref:System.StackOverflowException> durum oluşur `Try` veya `Catch` bloğu.</span><span class="sxs-lookup"><span data-stu-id="315d1-173">A <xref:System.StackOverflowException> is thrown in the `Try` or `Catch` block.</span></span>  
  
 <span data-ttu-id="315d1-174">Açıkça yürütme içine aktarmak için geçerli değil bir `Finally` bloğu.</span><span class="sxs-lookup"><span data-stu-id="315d1-174">It is not valid to explicitly transfer execution into a `Finally` block.</span></span> <span data-ttu-id="315d1-175">Yürütülmesi dışarı aktarma bir `Finally` blok bir özel durum geçerli değil, dışında.</span><span class="sxs-lookup"><span data-stu-id="315d1-175">Transferring execution out of a `Finally` block is not valid, except through an exception.</span></span>  
  
 <span data-ttu-id="315d1-176">Varsa bir `Try` deyimi en az bir içermiyor `Catch` bloğu içermesi gereken bir `Finally` bloğu.</span><span class="sxs-lookup"><span data-stu-id="315d1-176">If a `Try` statement does not contain at least one `Catch` block, it must contain a `Finally` block.</span></span>  
  
> [!TIP]
>  <span data-ttu-id="315d1-177">Özel durumları yakalamak yoksa `Using` deyimi davranır gibi bir `Try…Finally` bloğu ve blok çıkmak nasıl bakılmaksızın kaynakların garanti elden.</span><span class="sxs-lookup"><span data-stu-id="315d1-177">If you do not have to catch specific exceptions, the `Using` statement behaves like a `Try…Finally` block, and guarantees disposal of the resources, regardless of how you exit the block.</span></span> <span data-ttu-id="315d1-178">İşlenmeyen bir özel durumla bile bu geçerlidir.</span><span class="sxs-lookup"><span data-stu-id="315d1-178">This is true even with an unhandled exception.</span></span> <span data-ttu-id="315d1-179">Daha fazla bilgi için bkz: [kullanarak deyimi](../../../visual-basic/language-reference/statements/using-statement.md).</span><span class="sxs-lookup"><span data-stu-id="315d1-179">For more information, see [Using Statement](../../../visual-basic/language-reference/statements/using-statement.md).</span></span>  
  
## <a name="exception-argument"></a><span data-ttu-id="315d1-180">Özel durum bağımsız değişken</span><span class="sxs-lookup"><span data-stu-id="315d1-180">Exception Argument</span></span>  
 <span data-ttu-id="315d1-181">`Catch` Blok `exception` bağımsız değişkeni bir örneğidir <xref:System.Exception> sınıf veya türeyen bir sınıf `Exception` sınıfı.</span><span class="sxs-lookup"><span data-stu-id="315d1-181">The `Catch` block `exception` argument is an instance of the <xref:System.Exception> class or a class that derives from the `Exception` class.</span></span> <span data-ttu-id="315d1-182">`Exception` Karşılık gelen sınıf örneği oluştu hata `Try` bloğu.</span><span class="sxs-lookup"><span data-stu-id="315d1-182">The `Exception` class instance corresponds to the error that occurred in the `Try` block.</span></span>  
  
 <span data-ttu-id="315d1-183">Özelliklerini `Exception` nesne neden ve bir özel durum konumunu belirlemek için Yardım.</span><span class="sxs-lookup"><span data-stu-id="315d1-183">The properties of the `Exception` object help to identify the cause and location of an exception.</span></span> <span data-ttu-id="315d1-184">Örneğin, <xref:System.Exception.StackTrace%2A> özelliği için kod hatanın oluştuğu bulmanıza yardımcı olacak özel neden çağrılan yöntemler listeler.</span><span class="sxs-lookup"><span data-stu-id="315d1-184">For example, the <xref:System.Exception.StackTrace%2A> property lists the called methods that led to the exception, helping you find where the error occurred in the code.</span></span> <span data-ttu-id="315d1-185"><xref:System.Exception.Message%2A>özel durumu açıklayan bir ileti döndürür.</span><span class="sxs-lookup"><span data-stu-id="315d1-185"><xref:System.Exception.Message%2A> returns a message that describes the exception.</span></span> <span data-ttu-id="315d1-186"><xref:System.Exception.HelpLink%2A>bir bağlantı için ilişkili bir Yardım dosyası döndürür.</span><span class="sxs-lookup"><span data-stu-id="315d1-186"><xref:System.Exception.HelpLink%2A> returns a link to an associated Help file.</span></span> <span data-ttu-id="315d1-187"><xref:System.Exception.InnerException%2A>döndürür `Exception` veya geçerli özel durumun nedeni nesnesi döndüren `Nothing` hiçbir özgün ise `Exception`.</span><span class="sxs-lookup"><span data-stu-id="315d1-187"><xref:System.Exception.InnerException%2A> returns the `Exception` object that caused the current exception, or it returns `Nothing` if there is no original `Exception`.</span></span>  
  
## <a name="considerations-when-using-a-trycatch-statement"></a><span data-ttu-id="315d1-188">Try kullanmayla ilgili konular... Catch deyimi</span><span class="sxs-lookup"><span data-stu-id="315d1-188">Considerations When Using a Try…Catch Statement</span></span>  
 <span data-ttu-id="315d1-189">Kullanım bir `Try…Catch` deyimi yalnızca olağan dışı ya da beklenmeyen program olayları oluşumunu sinyal.</span><span class="sxs-lookup"><span data-stu-id="315d1-189">Use a `Try…Catch` statement only to signal the occurrence of unusual or unanticipated program events.</span></span> <span data-ttu-id="315d1-190">Bunun nedeni şunlardır:</span><span class="sxs-lookup"><span data-stu-id="315d1-190">Reasons for this include the following:</span></span>  
  
-   <span data-ttu-id="315d1-191">Çalışma zamanında özel durumları yakalama ek yükü oluşturur ve özel durumları önlemek için önceden denetimi daha yavaş olması olasıdır.</span><span class="sxs-lookup"><span data-stu-id="315d1-191">Catching exceptions at runtime creates additional overhead, and is likely to be slower than pre-checking to avoid exceptions.</span></span>  
  
-   <span data-ttu-id="315d1-192">Varsa bir `Catch` blok doğru şekilde işlenmez, özel durum kullanıcılara doğru bildirmemiş.</span><span class="sxs-lookup"><span data-stu-id="315d1-192">If a `Catch` block is not handled correctly, the exception might not be reported correctly to users.</span></span>  
  
-   <span data-ttu-id="315d1-193">Özel durum işleme bir programı daha karmaşık hale getirir.</span><span class="sxs-lookup"><span data-stu-id="315d1-193">Exception handling makes a program more complex.</span></span>  
  
 <span data-ttu-id="315d1-194">Her zaman ihtiyacınız olmayan bir `Try…Catch` deyimi oluştuğu için bir koşul denetleyin.</span><span class="sxs-lookup"><span data-stu-id="315d1-194">You do not always need a `Try…Catch` statement to check for a condition that is likely to occur.</span></span> <span data-ttu-id="315d1-195">Aşağıdaki örnek, bir dosyayı açmaya denemeden önce mevcut olup olmadığını denetler.</span><span class="sxs-lookup"><span data-stu-id="315d1-195">The following example checks whether a file exists before trying to open it.</span></span> <span data-ttu-id="315d1-196">Bu tarafından oluşturulan bir özel durum yakalama gereksinimini azaltır <xref:System.IO.File.OpenText%2A> yöntemi.</span><span class="sxs-lookup"><span data-stu-id="315d1-196">This reduces the need for catching an exception thrown by the <xref:System.IO.File.OpenText%2A> method.</span></span>  
  
 [!code-vb[VbVbalrStatements#94](../../../visual-basic/language-reference/error-messages/codesnippet/VisualBasic/try-catch-finally-statement_1.vb)]  
  
 <span data-ttu-id="315d1-197">Bu kodu olun `Catch` blokları düzgün raporlama yapabilir, kullanıcılara özel durumları iş parçacığı günlüğü veya uygun iletileri üzerinden.</span><span class="sxs-lookup"><span data-stu-id="315d1-197">Ensure that code in `Catch` blocks can properly report exceptions to users, whether through thread-safe logging or appropriate messages.</span></span> <span data-ttu-id="315d1-198">Aksi takdirde, özel durumlar bilinmeyen kalabilir.</span><span class="sxs-lookup"><span data-stu-id="315d1-198">Otherwise, exceptions might remain unknown.</span></span>  
  
## <a name="async-methods"></a><span data-ttu-id="315d1-199">Zaman uyumsuz yöntemleri</span><span class="sxs-lookup"><span data-stu-id="315d1-199">Async Methods</span></span>  
 <span data-ttu-id="315d1-200">Bir yöntem ile işaretlerseniz [zaman uyumsuz](../../../visual-basic/language-reference/modifiers/async.md) kullanabileceğiniz değiştiricisi, [bekleme](../../../visual-basic/language-reference/operators/await-operator.md) yönteminde işleci.</span><span class="sxs-lookup"><span data-stu-id="315d1-200">If you mark a method with the [Async](../../../visual-basic/language-reference/modifiers/async.md) modifier, you can use the [Await](../../../visual-basic/language-reference/operators/await-operator.md) operator in the method.</span></span> <span data-ttu-id="315d1-201">With deyimi `Await` işleci awaited görevi tamamlanana kadar yönteminin yürütülmesi askıya alır.</span><span class="sxs-lookup"><span data-stu-id="315d1-201">A statement with the `Await` operator suspends execution of the method until the awaited task completes.</span></span> <span data-ttu-id="315d1-202">Görev devam eden iş temsil eder.</span><span class="sxs-lookup"><span data-stu-id="315d1-202">The task represents ongoing work.</span></span> <span data-ttu-id="315d1-203">Zaman ile ilişkili görevi `Await` işleci tamamlandıktan, aynı yönteminde yürütme sürdürür.</span><span class="sxs-lookup"><span data-stu-id="315d1-203">When the task that's associated with the `Await` operator finishes, execution resumes in the same method.</span></span> <span data-ttu-id="315d1-204">Daha fazla bilgi için bkz: [zaman uyumsuz programlarda denetim akışı](../../../visual-basic/programming-guide/concepts/async/control-flow-in-async-programs.md).</span><span class="sxs-lookup"><span data-stu-id="315d1-204">For more information, see [Control Flow in Async Programs](../../../visual-basic/programming-guide/concepts/async/control-flow-in-async-programs.md).</span></span>  
  
 <span data-ttu-id="315d1-205">Zaman uyumsuz yöntem tarafından döndürülen bir görev, işlenmeyen bir özel durum nedeniyle tamamlandı belirten bir hatalı durumda bitebilir.</span><span class="sxs-lookup"><span data-stu-id="315d1-205">A task returned by an Async method may end in a faulted state, indicating that it completed due to an unhandled exception.</span></span> <span data-ttu-id="315d1-206">Bir görev ayrıca sonuçlanan bir iptal edilmiş durumda sonuna bir `OperationCanceledException` bekleme ifade dışında oluşturulan.</span><span class="sxs-lookup"><span data-stu-id="315d1-206">A task may also end in a canceled state, which results in an `OperationCanceledException` being thrown out of the await expression.</span></span> <span data-ttu-id="315d1-207">Özel durum iki tür çekmek için koyun `Await` görevde ile ilişkili ifade bir `Try` engelleme ve catch özel durum `Catch` blok.</span><span class="sxs-lookup"><span data-stu-id="315d1-207">To catch either type of exception, place the `Await` expression that's associated with the task in a `Try` block, and catch the exception in the `Catch` block.</span></span> <span data-ttu-id="315d1-208">Bir örnek, bu konunun ilerleyen bölümlerinde sağlanmıştır.</span><span class="sxs-lookup"><span data-stu-id="315d1-208">An example is provided later in this topic.</span></span>  
  
 <span data-ttu-id="315d1-209">Birden çok özel durum, hatalı için sorumlu için bir görev hatalı bir durumda olabilir.</span><span class="sxs-lookup"><span data-stu-id="315d1-209">A task can be in a faulted state because multiple exceptions were responsible for its faulting.</span></span> <span data-ttu-id="315d1-210">Örneğin, görev için bir çağrı sonucunu olabilir <xref:System.Threading.Tasks.Task.WhenAll%2A?displayProperty=nameWithType>.</span><span class="sxs-lookup"><span data-stu-id="315d1-210">For example, the task might be the result of a call to <xref:System.Threading.Tasks.Task.WhenAll%2A?displayProperty=nameWithType>.</span></span> <span data-ttu-id="315d1-211">Bu tür bir görev await, yakalanan özel durum yalnızca özel durumlar biridir ve hangi özel durumu yakalandı tahmin edilemez.</span><span class="sxs-lookup"><span data-stu-id="315d1-211">When you await such a task, the caught exception is only one of the exceptions, and you can't predict which exception will be caught.</span></span> <span data-ttu-id="315d1-212">Bir örnek, bu konunun ilerleyen bölümlerinde sağlanmıştır.</span><span class="sxs-lookup"><span data-stu-id="315d1-212">An example is provided later in this topic.</span></span>  
  
 <span data-ttu-id="315d1-213">Bir `Await` ifade içinde olamaz bir `Catch` blok veya `Finally` bloğu.</span><span class="sxs-lookup"><span data-stu-id="315d1-213">An `Await` expression can't be inside a `Catch` block or `Finally` block.</span></span>  
  
## <a name="iterators"></a><span data-ttu-id="315d1-214">Yineleyiciler</span><span class="sxs-lookup"><span data-stu-id="315d1-214">Iterators</span></span>  
 <span data-ttu-id="315d1-215">Yineleyici işlevi veya `Get` erişimci gerçekleştiren özel bir yineleme içinde bir koleksiyon.</span><span class="sxs-lookup"><span data-stu-id="315d1-215">An iterator function or `Get` accessor performs a custom iteration over a collection.</span></span> <span data-ttu-id="315d1-216">Yineleyici kullanan bir [verim](../../../visual-basic/language-reference/statements/yield-statement.md) deyimi her birer birer koleksiyonun bir öğesi döndürür.</span><span class="sxs-lookup"><span data-stu-id="315d1-216">An iterator uses a [Yield](../../../visual-basic/language-reference/statements/yield-statement.md) statement to return each element of the collection one at a time.</span></span> <span data-ttu-id="315d1-217">Kullanarak bir yineleyici işlevi çağırmak bir [For Each... Sonraki deyim](../../../visual-basic/language-reference/statements/for-each-next-statement.md).</span><span class="sxs-lookup"><span data-stu-id="315d1-217">You call an iterator function by using a [For Each...Next Statement](../../../visual-basic/language-reference/statements/for-each-next-statement.md).</span></span>  
  
 <span data-ttu-id="315d1-218">A `Yield` deyimi içinde bulunabilir bir `Try` bloğu.</span><span class="sxs-lookup"><span data-stu-id="315d1-218">A `Yield` statement can be inside a `Try` block.</span></span> <span data-ttu-id="315d1-219">A `Try` içeren blok bir `Yield` deyimi olabilir `Catch` engeller ve olabilir bir `Finally` bloğu.</span><span class="sxs-lookup"><span data-stu-id="315d1-219">A `Try` block that contains a `Yield` statement can have `Catch` blocks, and can have a `Finally` block.</span></span> <span data-ttu-id="315d1-220">"Deneyin blokları Visual Basic" bölümüne bakın [yineleyiciler](http://msdn.microsoft.com/library/f45331db-d595-46ec-9142-551d3d1eb1a7) bir örnek.</span><span class="sxs-lookup"><span data-stu-id="315d1-220">See the "Try Blocks in Visual Basic" section of [Iterators](http://msdn.microsoft.com/library/f45331db-d595-46ec-9142-551d3d1eb1a7) for an example.</span></span>  
  
 <span data-ttu-id="315d1-221">A `Yield` deyimi içinde olamaz bir `Catch` blok veya `Finally` bloğu.</span><span class="sxs-lookup"><span data-stu-id="315d1-221">A `Yield` statement cannot be inside a `Catch` block or a `Finally` block.</span></span>  
  
 <span data-ttu-id="315d1-222">Varsa `For Each` gövdesi (dışında yineleyici işlevi) bir özel durum oluşturur bir `Catch` yineleyici işlevi bloğunda yürütülmez, ancak bir `Finally` yineleyici işlevi bloğunda gerçekleştirilir.</span><span class="sxs-lookup"><span data-stu-id="315d1-222">If the `For Each` body (outside of the iterator function) throws an exception, a `Catch` block in the iterator function is not executed, but a `Finally` block in the iterator function is executed.</span></span> <span data-ttu-id="315d1-223">A `Catch` yineleyici işlevi bloğunda yineleyici işlevinin içinde oluşan özel durumlarını yakalar.</span><span class="sxs-lookup"><span data-stu-id="315d1-223">A `Catch` block inside an iterator function catches only exceptions that occur inside the iterator function.</span></span>  
  
## <a name="partial-trust-situations"></a><span data-ttu-id="315d1-224">Kısmi güven durumları</span><span class="sxs-lookup"><span data-stu-id="315d1-224">Partial-Trust Situations</span></span>  
 <span data-ttu-id="315d1-225">Kısmi güven durumlarda, bir ağ paylaşımında barındırılan bir uygulama gibi `Try...Catch...Finally` çağrı içeren yöntemi çağrılmadan önce oluşan güvenlik özel durumları yakalamaz.</span><span class="sxs-lookup"><span data-stu-id="315d1-225">In partial-trust situations, such as an application hosted on a network share, `Try...Catch...Finally` does not catch security exceptions that occur before the method that contains the call is invoked.</span></span> <span data-ttu-id="315d1-226">Aşağıdaki örnek, onu bir sunucu paylaşımı ve Çalıştır buradan geçirdiğinizde, hata üretir "System.Security.SecurityException: isteği başarısız oldu."</span><span class="sxs-lookup"><span data-stu-id="315d1-226">The following example, when you put it on a server share and run from there, produces the error "System.Security.SecurityException: Request Failed."</span></span> <span data-ttu-id="315d1-227">Güvenlik özel durumları hakkında daha fazla bilgi için bkz: <xref:System.Security.SecurityException> sınıfı.</span><span class="sxs-lookup"><span data-stu-id="315d1-227">For more information about security exceptions, see the <xref:System.Security.SecurityException> class.</span></span>  
  
 [!code-vb[VbVbalrStatements#85](../../../visual-basic/language-reference/error-messages/codesnippet/VisualBasic/try-catch-finally-statement_2.vb)]  
  
 <span data-ttu-id="315d1-228">Böyle bir kısmi güven durumda, yerine koymak zorunda `Process.Start` ayrı bir deyimde `Sub`.</span><span class="sxs-lookup"><span data-stu-id="315d1-228">In such a partial-trust situation, you have to put the `Process.Start` statement in a separate `Sub`.</span></span> <span data-ttu-id="315d1-229">İlk çağrısı `Sub` başarısız olur.</span><span class="sxs-lookup"><span data-stu-id="315d1-229">The initial call to the `Sub` will fail.</span></span> <span data-ttu-id="315d1-230">Böylece `Try...Catch` önce yakalamak için `Sub` içeren `Process.Start` başlatılır ve güvenlik özel durum üretti.</span><span class="sxs-lookup"><span data-stu-id="315d1-230">This enables `Try...Catch` to catch it before the `Sub` that contains `Process.Start` is started and the security exception produced.</span></span>  
  
## <a name="example"></a><span data-ttu-id="315d1-231">Örnek</span><span class="sxs-lookup"><span data-stu-id="315d1-231">Example</span></span>  
 <span data-ttu-id="315d1-232">Aşağıdaki örnek yapısını gösterilmektedir `Try...Catch...Finally` deyimi.</span><span class="sxs-lookup"><span data-stu-id="315d1-232">The following example illustrates the structure of the `Try...Catch...Finally` statement.</span></span>  
  
 [!code-vb[VbVbalrStatements#86](../../../visual-basic/language-reference/error-messages/codesnippet/VisualBasic/try-catch-finally-statement_3.vb)]  
  
## <a name="example"></a><span data-ttu-id="315d1-233">Örnek</span><span class="sxs-lookup"><span data-stu-id="315d1-233">Example</span></span>  
 <span data-ttu-id="315d1-234">Aşağıdaki örnekte, `CreateException` yöntemi atar bir `NullReferenceException`.</span><span class="sxs-lookup"><span data-stu-id="315d1-234">In the following example, the `CreateException` method throws a `NullReferenceException`.</span></span> <span data-ttu-id="315d1-235">Özel durum oluşturur kodu kullanımda olmayan bir `Try` bloğu.</span><span class="sxs-lookup"><span data-stu-id="315d1-235">The code that generates the exception is not in a `Try` block.</span></span> <span data-ttu-id="315d1-236">Bu nedenle, `CreateException` yöntemi özel durum işlemez.</span><span class="sxs-lookup"><span data-stu-id="315d1-236">Therefore, the `CreateException` method does not handle the exception.</span></span> <span data-ttu-id="315d1-237">`RunSample` Olduğundan, yöntemi özel durum işleme çağrısı `CreateException` yöntemi olan bir `Try` bloğu.</span><span class="sxs-lookup"><span data-stu-id="315d1-237">The `RunSample` method does handle the exception because the call to the `CreateException` method is in a `Try` block.</span></span>  
  
 <span data-ttu-id="315d1-238">Örnek içerir `Catch` deyimleri için özel durumlar, çeşitli türlerde sıralı en belirli en genel.</span><span class="sxs-lookup"><span data-stu-id="315d1-238">The example includes `Catch` statements for several types of exceptions, ordered from the most specific to the most general.</span></span>  
  
 [!code-vb[VbVbalrStatements#91](../../../visual-basic/language-reference/error-messages/codesnippet/VisualBasic/try-catch-finally-statement_4.vb)]  
  
## <a name="example"></a><span data-ttu-id="315d1-239">Örnek</span><span class="sxs-lookup"><span data-stu-id="315d1-239">Example</span></span>  
 <span data-ttu-id="315d1-240">Aşağıdaki örnekte nasıl kullanılacağını gösteren bir `Catch When` koşullu bir deyime filtre ifadesi.</span><span class="sxs-lookup"><span data-stu-id="315d1-240">The following example shows how to use a `Catch When` statement to filter on a conditional expression.</span></span> <span data-ttu-id="315d1-241">Koşullu ifade değerlendirilirse `True`, kodda `Catch` engelleme çalıştırır.</span><span class="sxs-lookup"><span data-stu-id="315d1-241">If the conditional expression evaluates to `True`, the code in the `Catch` block runs.</span></span>  
  
 [!code-vb[VbVbalrStatements#92](../../../visual-basic/language-reference/error-messages/codesnippet/VisualBasic/try-catch-finally-statement_5.vb)]  
  
## <a name="example"></a><span data-ttu-id="315d1-242">Örnek</span><span class="sxs-lookup"><span data-stu-id="315d1-242">Example</span></span>  
 <span data-ttu-id="315d1-243">Aşağıdaki örnek sahip bir `Try…Catch` bulunan deyimi bir `Try` bloğu.</span><span class="sxs-lookup"><span data-stu-id="315d1-243">The following example has a `Try…Catch` statement that is contained in a `Try` block.</span></span> <span data-ttu-id="315d1-244">İç `Catch` blok sahip bir özel durum oluşturur, `InnerException` özelliği için orijinal özel durumu için ayarlanmış.</span><span class="sxs-lookup"><span data-stu-id="315d1-244">The inner `Catch` block throws an exception that has its `InnerException` property set to the original exception.</span></span> <span data-ttu-id="315d1-245">Dış `Catch` blok raporlarını kendi özel ve iç özel durum.</span><span class="sxs-lookup"><span data-stu-id="315d1-245">The outer `Catch` block reports its own exception and the inner exception.</span></span>  
  
 [!code-vb[VbVbalrStatements#93](../../../visual-basic/language-reference/error-messages/codesnippet/VisualBasic/try-catch-finally-statement_6.vb)]  
  
## <a name="example"></a><span data-ttu-id="315d1-246">Örnek</span><span class="sxs-lookup"><span data-stu-id="315d1-246">Example</span></span>  
 <span data-ttu-id="315d1-247">Aşağıdaki örnek, özel durum işleme için zaman uyumsuz yöntemleri gösterilmektedir.</span><span class="sxs-lookup"><span data-stu-id="315d1-247">The following example illustrates exception handling for async methods.</span></span> <span data-ttu-id="315d1-248">Bir zaman uyumsuz görev için geçerli bir özel durum yakalamak için `Await` ifade konusu bir `Try` bloğunu çağıran ve özel durum yakalandı içinde `Catch` bloğu.</span><span class="sxs-lookup"><span data-stu-id="315d1-248">To catch an exception that applies to an async task, the `Await` expression is in a `Try` block of the caller, and the exception is caught in the `Catch` block.</span></span>  
  
 <span data-ttu-id="315d1-249">Açıklamadan çıkarın `Throw New Exception` özel durum işleme göstermek için örnekte satır.</span><span class="sxs-lookup"><span data-stu-id="315d1-249">Uncomment the `Throw New Exception` line in the example to demonstrate exception handling.</span></span> <span data-ttu-id="315d1-250">Özel durumun yakalandığı `Catch` engellemek, görevin `IsFaulted` özelliği ayarlanmış `True`ve görevin `Exception.InnerException` özelliği, özel durumu ayarlanır.</span><span class="sxs-lookup"><span data-stu-id="315d1-250">The exception is caught in the `Catch` block, the task's `IsFaulted` property is set to `True`, and the task's `Exception.InnerException` property is set to the exception.</span></span>  
  
 <span data-ttu-id="315d1-251">Açıklamadan çıkarın `Throw New OperationCancelledException` satır zaman uyumsuz bir işlem iptal ettiğinizde ne olacağını gösterir.</span><span class="sxs-lookup"><span data-stu-id="315d1-251">Uncomment the `Throw New OperationCancelledException` line to demonstrate what happens when you cancel an asynchronous process.</span></span> <span data-ttu-id="315d1-252">Özel durumun yakalandığı `Catch` bloğu ve görevin `IsCanceled` özelliği ayarlanmış `True`.</span><span class="sxs-lookup"><span data-stu-id="315d1-252">The exception is caught in the `Catch` block, and the task's `IsCanceled` property is set to `True`.</span></span> <span data-ttu-id="315d1-253">Ancak, bu örnek için uygulama bazı koşullar altında `IsFaulted` ayarlanır `True` ve `IsCanceled` ayarlanır `False`.</span><span class="sxs-lookup"><span data-stu-id="315d1-253">However, under some conditions that don't apply to this example, `IsFaulted` is set to `True` and `IsCanceled` is set to `False`.</span></span>  
  
 [!code-vb[csAsyncExceptions#1](../../../csharp/language-reference/keywords/codesnippet/VisualBasic/try-catch-finally-statement_7.vb)]  
  
## <a name="example"></a><span data-ttu-id="315d1-254">Örnek</span><span class="sxs-lookup"><span data-stu-id="315d1-254">Example</span></span>  
 <span data-ttu-id="315d1-255">Aşağıdaki örnek, birden çok görev birden çok özel durumları burada sonuçlanabilir özel durum işleme gösterilmektedir.</span><span class="sxs-lookup"><span data-stu-id="315d1-255">The following example illustrates exception handling where multiple tasks can result in multiple exceptions.</span></span> <span data-ttu-id="315d1-256">`Try` Bloğu `Await` ifade görev için <xref:System.Threading.Tasks.Task.WhenAll%2A?displayProperty=nameWithType> döndürdü.</span><span class="sxs-lookup"><span data-stu-id="315d1-256">The `Try` block has the `Await` expression for the task that <xref:System.Threading.Tasks.Task.WhenAll%2A?displayProperty=nameWithType> returned.</span></span> <span data-ttu-id="315d1-257">Üç için görevleri, görev tamamlandığında <xref:System.Threading.Tasks.Task.WhenAll%2A?displayProperty=nameWithType> uygulanan tamamlandığından.</span><span class="sxs-lookup"><span data-stu-id="315d1-257">The task is complete when the three tasks to which <xref:System.Threading.Tasks.Task.WhenAll%2A?displayProperty=nameWithType> is applied are complete.</span></span>  
  
 <span data-ttu-id="315d1-258">Her biri üç görev bir özel durum oluşur.</span><span class="sxs-lookup"><span data-stu-id="315d1-258">Each of the three tasks causes an exception.</span></span> <span data-ttu-id="315d1-259">`Catch` Blok tekrarlanan bulunan özel durumlar aracılığıyla `Exception.InnerExceptions` görev özelliği, `Task.WhenAll` döndürdü.</span><span class="sxs-lookup"><span data-stu-id="315d1-259">The `Catch` block iterates through the exceptions, which are found in the `Exception.InnerExceptions` property of the task that `Task.WhenAll` returned.</span></span>  
  
 [!code-vb[csAsyncExceptions#3](../../../csharp/language-reference/keywords/codesnippet/VisualBasic/try-catch-finally-statement_8.vb)]  
  
## <a name="see-also"></a><span data-ttu-id="315d1-260">Ayrıca Bkz.</span><span class="sxs-lookup"><span data-stu-id="315d1-260">See Also</span></span>  
 <xref:Microsoft.VisualBasic.Information.Err%2A>  
 <xref:System.Exception>  
 [<span data-ttu-id="315d1-261">Exit deyimi</span><span class="sxs-lookup"><span data-stu-id="315d1-261">Exit Statement</span></span>](../../../visual-basic/language-reference/statements/exit-statement.md)  
 [<span data-ttu-id="315d1-262">On Error deyimi</span><span class="sxs-lookup"><span data-stu-id="315d1-262">On Error Statement</span></span>](../../../visual-basic/language-reference/statements/on-error-statement.md)  
 [<span data-ttu-id="315d1-263">Kod parçacıkları için en iyi uygulamalar</span><span class="sxs-lookup"><span data-stu-id="315d1-263">Best Practices for Using Code Snippets</span></span>](/visualstudio/ide/best-practices-for-using-code-snippets)  
 [<span data-ttu-id="315d1-264">Özel durum işleme</span><span class="sxs-lookup"><span data-stu-id="315d1-264">Exception Handling</span></span>](https://msdn.microsoft.com/library/dd997415)  
 [<span data-ttu-id="315d1-265">Throw deyimi</span><span class="sxs-lookup"><span data-stu-id="315d1-265">Throw Statement</span></span>](../../../visual-basic/language-reference/statements/throw-statement.md)
